Workbook

Sheet TestData
A1: Emp_ID | B1: Name | C1: Department | D1: Region | E1: Email | F1: Join_Date | G1: Salary | H1: Bonus | I1: Hours_Worked | J1: Overtime | K1: Sales_Q1 | L1: Sales_Q2 | M1: Sales_Q3 | N1: Sales_Q4 | O1: Target | P1: Active | Q1: Manager_ID | R1: Phone | S1: Notes | T1: Code | U1: SKU | V1: Category | W1: Total_Sales | X1: Achieved_% | Y1: Bonus_Eligible | Z1: Email_Domain | AA1: Year_Joined | AB1: Dept_CostCenter | AC1: Region_City | AD1: Name_Upper | AE1: Target_Gap | AF1: IFERROR_Demo
A2: E0001 | B2: Trần An | C2: Ops | D2: DN | E2: an.trần@contoso.vn | F2: 44957 | G2: 29081788 | H2: 4925583 | I2: 175.7 | J2: 0 | K2: 299467210 | L2: 126737383 | M2: 161190146 | N2: 138409749 | O2: 392285876 | P2: TRUE | Q2: E0001 | R2: 0982458591 | S2: đã ký HĐ | T2: OP-001-A | U2: SKU-98696 | V2: A | W2: =SUM(tblData[@Sales_Q1]:tblData[@Sales_Q4]) -> 0 | X2: =IF(tblData[@Target]=0,0, SUM(tblData[@Sales_Q1]:tblData[@Sales_Q4])/tblData[@Target]) -> 0 | Y2: =IF([@[Achieved_%]]>=1,"Yes","No") -> 0 | Z2: =RIGHT(tblData[@Email],LEN(tblData[@Email])-FIND("@",tblData[@Email])) -> 0 | AA2: =YEAR(tblData[@Join_Date]) -> 0 | AB2: {=_xlfn.XLOOKUP(tblData[@Department],Dept!A:A,Dept!B:B,"N/A")} -> 0 | AC2: {=_xlfn.XLOOKUP(tblData[@Region],Region!A:A,Region!B:B,"N/A")} -> 0 | AD2: =UPPER(tblData[@Name]) -> 0 | AE2: =[@Total_Sales]-tblData[@Target] -> 0 | AF2: =IFERROR(VALUE(MID(tblData[@Code],4,3)),"ERR") -> 0
A3: E0002 | B3: Nguyễn An | C3: Sales | D3: HN | E3: an.nguyễn@contoso.vn | F3: 44600 | G3: 21953367 | H3: 4752652 | I3: 157 | J3: 0 | K3: 294061375 | L3: 300845460 | M3: 282968651 | N3: 156328085 | O3: 180349564 | P3: TRUE | Q3: E0005 | R3: 0938536477 | S3: Needs follow-up | T3: SA-002-A | U3: SKU-64987 | V3: A | W3: =SUM(tblData[@Sales_Q1]:tblData[@Sales_Q4]) -> 0 | X3: =IF(tblData[@Target]=0,0, SUM(tblData[@Sales_Q1]:tblData[@Sales_Q4])/tblData[@Target]) -> 0 | Y3: =IF([@[Achieved_%]]>=1,"Yes","No") -> 0 | Z3: =RIGHT(tblData[@Email],LEN(tblData[@Email])-FIND("@",tblData[@Email])) -> 0 | AA3: =YEAR(tblData[@Join_Date]) -> 0 | AB3: {=_xlfn.XLOOKUP(tblData[@Department],Dept!A:A,Dept!B:B,"N/A")} -> 0 | AC3: {=_xlfn.XLOOKUP(tblData[@Region],Region!A:A,Region!B:B,"N/A")} -> 0 | AD3: =UPPER(tblData[@Name]) -> 0 | AE3: =[@Total_Sales]-tblData[@Target] -> 0 | AF3: =IFERROR(VALUE(MID(tblData[@Code],4,3)),"ERR") -> 0
A4: E0003 | B4: Nguyễn Hà | C4: Ops | D4: CT | E4: hà.nguyễn@example.com | F4: 44578 | G4: 39943512 | H4: 4323718 | I4: 188.9 | J4: 12.9 | K4: 112250665 | L4: 250427519 | M4: 231009883 | N4: 398192957 | O4: 539151677 | P4: TRUE | Q4: E0003 | R4: 0917374122 | S4: Needs follow-up | T4: OP-003-B | U4: SKU-23396 | V4: B | W4: =SUM(tblData[@Sales_Q1]:tblData[@Sales_Q4]) -> 0 | X4: =IF(tblData[@Target]=0,0, SUM(tblData[@Sales_Q1]:tblData[@Sales_Q4])/tblData[@Target]) -> 0 | Y4: =IF([@[Achieved_%]]>=1,"Yes","No") -> 0 | Z4: =RIGHT(tblData[@Email],LEN(tblData[@Email])-FIND("@",tblData[@Email])) -> 0 | AA4: =YEAR(tblData[@Join_Date]) -> 0 | AB4: {=_xlfn.XLOOKUP(tblData[@Department],Dept!A:A,Dept!B:B,"N/A")} -> 0 | AC4: {=_xlfn.XLOOKUP(tblData[@Region],Region!A:A,Region!B:B,"N/A")} -> 0 | AD4: =UPPER(tblData[@Name]) -> 0 | AE4: =[@Total_Sales]-tblData[@Target] -> 0 | AF4: =IFERROR(VALUE(MID(tblData[@Code],4,3)),"ERR") -> 0
A5: E0004 | B5: Huỳnh Minh | C5: Sales | D5: CT | E5: minh.huỳnh@contoso.vn | F5: 44517 | G5: 46702013 | H5: 4200134 | I5: 181.1 | J5: 5.1 | K5: 249502978 | L5: 287544070 | M5: 245524628 | N5: 374266824 | O5: 429394470 | P5: TRUE | R5: 0915918715 | S5: pending | T5: SA-004-C | U5: SKU-59615 | V5: C | W5: =SUM(tblData[@Sales_Q1]:tblData[@Sales_Q4]) -> 0 | X5: =IF(tblData[@Target]=0,0, SUM(tblData[@Sales_Q1]:tblData[@Sales_Q4])/tblData[@Target]) -> 0 | Y5: =IF([@[Achieved_%]]>=1,"Yes","No") -> 0 | Z5: =RIGHT(tblData[@Email],LEN(tblData[@Email])-FIND("@",tblData[@Email])) -> 0 | AA5: =YEAR(tblData[@Join_Date]) -> 0 | AB5: {=_xlfn.XLOOKUP(tblData[@Department],Dept!A:A,Dept!B:B,"N/A")} -> 0 | AC5: {=_xlfn.XLOOKUP(tblData[@Region],Region!A:A,Region!B:B,"N/A")} -> 0 | AD5: =UPPER(tblData[@Name]) -> 0 | AE5: =[@Total_Sales]-tblData[@Target] -> 0 | AF5: =IFERROR(VALUE(MID(tblData[@Code],4,3)),"ERR") -> 0
A6: E0005 | B6: Huỳnh Khánh | C6: Ops | D6: HCM | E6: khánh.huỳnh@company.vn | F6: 45128 | G6: 28193880 | H6: 6854676 | I6: 204.7 | J6: 28.7 | K6: 284564360 | L6: 118574553 | M6: 304403923 | N6: 329827822 | O6: 937110843 | P6: TRUE | Q6: E0001 | R6: 0917377459 | S6: đã ký HĐ | T6: OP-005-A | U6: SKU-40512 | V6: A | W6: =SUM(tblData[@Sales_Q1]:tblData[@Sales_Q4]) -> 0 | X6: =IF(tblData[@Target]=0,0, SUM(tblData[@Sales_Q1]:tblData[@Sales_Q4])/tblData[@Target]) -> 0 | Y6: =IF([@[Achieved_%]]>=1,"Yes","No") -> 0 | Z6: =RIGHT(tblData[@Email],LEN(tblData[@Email])-FIND("@",tblData[@Email])) -> 0 | AA6: =YEAR(tblData[@Join_Date]) -> 0 | AB6: {=_xlfn.XLOOKUP(tblData[@Department],Dept!A:A,Dept!B:B,"N/A")} -> 0 | AC6: {=_xlfn.XLOOKUP(tblData[@Region],Region!A:A,Region!B:B,"N/A")} -> 0 | AD6: =UPPER(tblData[@Name]) -> 0 | AE6: =[@Total_Sales]-tblData[@Target] -> 0 | AF6: =IFERROR(VALUE(MID(tblData[@Code],4,3)),"ERR") -> 0
A7: E0006 | B7: Huỳnh Hà | C7: Finance | D7: DN | E7: hà.huỳnh@contoso.vn | F7: 45309 | G7: 10669995 | H7: 1590206 | I7: 142.8 | J7: 0 | K7: 197405005 | L7: 118979792 | M7: 87709731 | N7: 295827121 | O7: 848027879 | P7: TRUE | Q7: E0001 | R7: 0929961380 | S7: thử nghiệm | T7: FI-006-A | U7: SKU-89840 | V7: A | W7: =SUM(tblData[@Sales_Q1]:tblData[@Sales_Q4]) -> 0 | X7: =IF(tblData[@Target]=0,0, SUM(tblData[@Sales_Q1]:tblData[@Sales_Q4])/tblData[@Target]) -> 0 | Y7: =IF([@[Achieved_%]]>=1,"Yes","No") -> 0 | Z7: =RIGHT(tblData[@Email],LEN(tblData[@Email])-FIND("@",tblData[@Email])) -> 0 | AA7: =YEAR(tblData[@Join_Date]) -> 0 | AB7: {=_xlfn.XLOOKUP(tblData[@Department],Dept!A:A,Dept!B:B,"N/A")} -> 0 | AC7: {=_xlfn.XLOOKUP(tblData[@Region],Region!A:A,Region!B:B,"N/A")} -> 0 | AD7: =UPPER(tblData[@Name]) -> 0 | AE7: =[@Total_Sales]-tblData[@Target] -> 0 | AF7: =IFERROR(VALUE(MID(tblData[@Code],4,3)),"ERR") -> 0
A8: E0007 | B8: Lê Uyên | C8: IT | D8: DN | E8: uyên.lê@company.vn | F8: 45242 | G8: 22091261 | H8: 3402354 | I8: 183.7 | J8: 7.7 | K8: 307072949 | L8: 184489564 | M8: 157944665 | N8: 371066539 | O8: 963891745 | P8: TRUE | Q8: E0001 | R8: 0906292423 | S8: Needs follow-up | T8: IT-007-C | U8: SKU-40021 | V8: C | W8: =SUM(tblData[@Sales_Q1]:tblData[@Sales_Q4]) -> 0 | X8: =IF(tblData[@Target]=0,0, SUM(tblData[@Sales_Q1]:tblData[@Sales_Q4])/tblData[@Target]) -> 0 | Y8: =IF([@[Achieved_%]]>=1,"Yes","No") -> 0 | Z8: =RIGHT(tblData[@Email],LEN(tblData[@Email])-FIND("@",tblData[@Email])) -> 0 | AA8: =YEAR(tblData[@Join_Date]) -> 0 | AB8: {=_xlfn.XLOOKUP(tblData[@Department],Dept!A:A,Dept!B:B,"N/A")} -> 0 | AC8: {=_xlfn.XLOOKUP(tblData[@Region],Region!A:A,Region!B:B,"N/A")} -> 0 | AD8: =UPPER(tblData[@Name]) -> 0 | AE8: =[@Total_Sales]-tblData[@Target] -> 0 | AF8: =IFERROR(VALUE(MID(tblData[@Code],4,3)),"ERR") -> 0
A9: E0008 | B9: Trần Khánh | C9: Marketing | D9: DN | E9: khánh.trần@example.com | F9: 44032 | G9: 26048957 | H9: 6130147 | I9: 198.2 | J9: 22.2 | K9: 378740110 | L9: 352554573 | M9: 354869078 | N9: 139482491 | O9: 344249720 | P9: FALSE | Q9: E0004 | R9: 0943342608 | S9: OK | T9: MA-008-A | U9: SKU-28726 | V9: A | W9: =SUM(tblData[@Sales_Q1]:tblData[@Sales_Q4]) -> 0 | X9: =IF(tblData[@Target]=0,0, SUM(tblData[@Sales_Q1]:tblData[@Sales_Q4])/tblData[@Target]) -> 0 | Y9: =IF([@[Achieved_%]]>=1,"Yes","No") -> 0 | Z9: =RIGHT(tblData[@Email],LEN(tblData[@Email])-FIND("@",tblData[@Email])) -> 0 | AA9: =YEAR(tblData[@Join_Date]) -> 0 | AB9: {=_xlfn.XLOOKUP(tblData[@Department],Dept!A:A,Dept!B:B,"N/A")} -> 0 | AC9: {=_xlfn.XLOOKUP(tblData[@Region],Region!A:A,Region!B:B,"N/A")} -> 0 | AD9: =UPPER(tblData[@Name]) -> 0 | AE9: =[@Total_Sales]-tblData[@Target] -> 0 | AF9: =IFERROR(VALUE(MID(tblData[@Code],4,3)),"ERR") -> 0
A10: E0009 | B10: Võ Minh | C10: Ops | D10: HP | E10: minh.võ@example.com | F10: 45556 | G10: 11366612 | H10: 1451919 | I10: 161.7 | J10: 0 | K10: 388175028 | L10: 182862715 | M10: 233378299 | N10: 161665644 | O10: 755264936 | P10: FALSE | Q10: E0002 | R10: 0972525206 | S10: VIP | T10: OP-009-B | U10: SKU-76784 | V10: B | W10: =SUM(tblData[@Sales_Q1]:tblData[@Sales_Q4]) -> 0 | X10: =IF(tblData[@Target]=0,0, SUM(tblData[@Sales_Q1]:tblData[@Sales_Q4])/tblData[@Target]) -> 0 | Y10: =IF([@[Achieved_%]]>=1,"Yes","No") -> 0 | Z10: =RIGHT(tblData[@Email],LEN(tblData[@Email])-FIND("@",tblData[@Email])) -> 0 | AA10: =YEAR(tblData[@Join_Date]) -> 0 | AB10: {=_xlfn.XLOOKUP(tblData[@Department],Dept!A:A,Dept!B:B,"N/A")} -> 0 | AC10: {=_xlfn.XLOOKUP(tblData[@Region],Region!A:A,Region!B:B,"N/A")} -> 0 | AD10: =UPPER(tblData[@Name]) -> 0 | AE10: =[@Total_Sales]-tblData[@Target] -> 0 | AF10: =IFERROR(VALUE(MID(tblData[@Code],4,3)),"ERR") -> 0
A11: E0010 | B11: Lê Hà | C11: Ops | D11: CT | E11: hà.lê@contoso.vn | F11: 45011 | G11: 30857742 | H11: 2562840 | I11: 141.3 | J11: 0 | K11: 257882760 | L11: 145540567 | M11: 135390464 | N11: 366606443 | O11: 336780295 | P11: TRUE | Q11: E0005 | R11: 0985218028 | S11: VIP | T11: OP-010-C | U11: SKU-71348 | V11: C | W11: =SUM(tblData[@Sales_Q1]:tblData[@Sales_Q4]) -> 0 | X11: =IF(tblData[@Target]=0,0, SUM(tblData[@Sales_Q1]:tblData[@Sales_Q4])/tblData[@Target]) -> 0 | Y11: =IF([@[Achieved_%]]>=1,"Yes","No") -> 0 | Z11: =RIGHT(tblData[@Email],LEN(tblData[@Email])-FIND("@",tblData[@Email])) -> 0 | AA11: =YEAR(tblData[@Join_Date]) -> 0 | AB11: {=_xlfn.XLOOKUP(tblData[@Department],Dept!A:A,Dept!B:B,"N/A")} -> 0 | AC11: {=_xlfn.XLOOKUP(tblData[@Region],Region!A:A,Region!B:B,"N/A")} -> 0 | AD11: =UPPER(tblData[@Name]) -> 0 | AE11: =[@Total_Sales]-tblData[@Target] -> 0 | AF11: =IFERROR(VALUE(MID(tblData[@Code],4,3)),"ERR") -> 0
A12: E0011 | B12: Trần Minh | C12: Ops | D12: DN | E12: minh.trần@example.com | F12: 45326 | G12: 20719242 | H12: 1859934 | I12: 196.9 | J12: 20.9 | K12: 222552610 | L12: 141355424 | M12: 368019332 | N12: 270335593 | O12: 615856742 | P12: TRUE | Q12: E0004 | R12: 0949398441 | S12: pending | T12: OP-011-A | U12: SKU-10425 | V12: A | W12: =SUM(tblData[@Sales_Q1]:tblData[@Sales_Q4]) -> 0 | X12: =IF(tblData[@Target]=0,0, SUM(tblData[@Sales_Q1]:tblData[@Sales_Q4])/tblData[@Target]) -> 0 | Y12: =IF([@[Achieved_%]]>=1,"Yes","No") -> 0 | Z12: =RIGHT(tblData[@Email],LEN(tblData[@Email])-FIND("@",tblData[@Email])) -> 0 | AA12: =YEAR(tblData[@Join_Date]) -> 0 | AB12: {=_xlfn.XLOOKUP(tblData[@Department],Dept!A:A,Dept!B:B,"N/A")} -> 0 | AC12: {=_xlfn.XLOOKUP(tblData[@Region],Region!A:A,Region!B:B,"N/A")} -> 0 | AD12: =UPPER(tblData[@Name]) -> 0 | AE12: =[@Total_Sales]-tblData[@Target] -> 0 | AF12: =IFERROR(VALUE(MID(tblData[@Code],4,3)),"ERR") -> 0
A13: E0012 | B13: Trần Ngọc | C13: Ops | D13: HP | E13: ngọc.trần@contoso.vn | F13: 44848 | G13: 35891752 | H13: 8362488 | I13: 208 | J13: 32 | K13: 369763211 | L13: 397454369 | M13: 322981039 | N13: 311917078 | O13: 875167677 | P13: TRUE | Q13: E0002 | R13: 0981009594 | S13: Needs follow-up | T13: OP-012-C | U13: SKU-80697 | V13: C | W13: =SUM(tblData[@Sales_Q1]:tblData[@Sales_Q4]) -> 0 | X13: =IF(tblData[@Target]=0,0, SUM(tblData[@Sales_Q1]:tblData[@Sales_Q4])/tblData[@Target]) -> 0 | Y13: =IF([@[Achieved_%]]>=1,"Yes","No") -> 0 | Z13: =RIGHT(tblData[@Email],LEN(tblData[@Email])-FIND("@",tblData[@Email])) -> 0 | AA13: =YEAR(tblData[@Join_Date]) -> 0 | AB13: {=_xlfn.XLOOKUP(tblData[@Department],Dept!A:A,Dept!B:B,"N/A")} -> 0 | AC13: {=_xlfn.XLOOKUP(tblData[@Region],Region!A:A,Region!B:B,"N/A")} -> 0 | AD13: =UPPER(tblData[@Name]) -> 0 | AE13: =[@Total_Sales]-tblData[@Target] -> 0 | AF13: =IFERROR(VALUE(MID(tblData[@Code],4,3)),"ERR") -> 0
A14: E0013 | B14: Vũ An | C14: Sales | D14: DN | E14: an.vũ@example.com | F14: 45582 | G14: 49542436 | H14: 9706415 | I14: 191 | J14: 15 | K14: 102453338 | L14: 313038498 | M14: 84045666 | N14: 96321408 | O14: 413183577 | P14: TRUE | Q14: E0005 | R14: 0919153566 | S14: pending | T14: SA-013-B | U14: SKU-20322 | V14: B | W14: =SUM(tblData[@Sales_Q1]:tblData[@Sales_Q4]) -> 0 | X14: =IF(tblData[@Target]=0,0, SUM(tblData[@Sales_Q1]:tblData[@Sales_Q4])/tblData[@Target]) -> 0 | Y14: =IF([@[Achieved_%]]>=1,"Yes","No") -> 0 | Z14: =RIGHT(tblData[@Email],LEN(tblData[@Email])-FIND("@",tblData[@Email])) -> 0 | AA14: =YEAR(tblData[@Join_Date]) -> 0 | AB14: {=_xlfn.XLOOKUP(tblData[@Department],Dept!A:A,Dept!B:B,"N/A")} -> 0 | AC14: {=_xlfn.XLOOKUP(tblData[@Region],Region!A:A,Region!B:B,"N/A")} -> 0 | AD14: =UPPER(tblData[@Name]) -> 0 | AE14: =[@Total_Sales]-tblData[@Target] -> 0 | AF14: =IFERROR(VALUE(MID(tblData[@Code],4,3)),"ERR") -> 0
A15: E0014 | B15: Lê Giang | C15: Ops | D15: CT | E15: giang.lê@contoso.vn | F15: 44333 | G15: 30944510 | H15: 3132007 | I15: 143.2 | J15: 0 | K15: 275661966 | L15: 159174313 | M15: 326323195 | N15: 379506482 | O15: 284987326 | P15: TRUE | Q15: E0005 | R15: 0934374754 | S15: Needs follow-up | T15: OP-014-C | U15: SKU-65461 | V15: C | W15: =SUM(tblData[@Sales_Q1]:tblData[@Sales_Q4]) -> 0 | X15: =IF(tblData[@Target]=0,0, SUM(tblData[@Sales_Q1]:tblData[@Sales_Q4])/tblData[@Target]) -> 0 | Y15: =IF([@[Achieved_%]]>=1,"Yes","No") -> 0 | Z15: =RIGHT(tblData[@Email],LEN(tblData[@Email])-FIND("@",tblData[@Email])) -> 0 | AA15: =YEAR(tblData[@Join_Date]) -> 0 | AB15: {=_xlfn.XLOOKUP(tblData[@Department],Dept!A:A,Dept!B:B,"N/A")} -> 0 | AC15: {=_xlfn.XLOOKUP(tblData[@Region],Region!A:A,Region!B:B,"N/A")} -> 0 | AD15: =UPPER(tblData[@Name]) -> 0 | AE15: =[@Total_Sales]-tblData[@Target] -> 0 | AF15: =IFERROR(VALUE(MID(tblData[@Code],4,3)),"ERR") -> 0
A16: E0015 | B16: Phan Phúc | C16: IT | D16: HP | E16: phúc.phan@contoso.vn | F16: 44694 | G16: 36433648 | H16: 4112309 | I16: 180.7 | J16: 4.7 | K16: 189871965 | L16: 111553124 | M16: 201968492 | N16: 221116174 | O16: 173841962 | P16: TRUE | Q16: E0001 | R16: 0904860684 | S16: thử nghiệm | T16: IT-015-B | U16: SKU-54313 | V16: B | W16: =SUM(tblData[@Sales_Q1]:tblData[@Sales_Q4]) -> 0 | X16: =IF(tblData[@Target]=0,0, SUM(tblData[@Sales_Q1]:tblData[@Sales_Q4])/tblData[@Target]) -> 0 | Y16: =IF([@[Achieved_%]]>=1,"Yes","No") -> 0 | Z16: =RIGHT(tblData[@Email],LEN(tblData[@Email])-FIND("@",tblData[@Email])) -> 0 | AA16: =YEAR(tblData[@Join_Date]) -> 0 | AB16: {=_xlfn.XLOOKUP(tblData[@Department],Dept!A:A,Dept!B:B,"N/A")} -> 0 | AC16: {=_xlfn.XLOOKUP(tblData[@Region],Region!A:A,Region!B:B,"N/A")} -> 0 | AD16: =UPPER(tblData[@Name]) -> 0 | AE16: =[@Total_Sales]-tblData[@Target] -> 0 | AF16: =IFERROR(VALUE(MID(tblData[@Code],4,3)),"ERR") -> 0
A17: E0016 | B17: Nguyễn Châu | C17: Ops | D17: HCM | E17: châu.nguyễn@example.com | F17: 44371 | G17: 30993420 | H17: 2026845 | I17: 163.2 | J17: 0 | K17: 205569237 | L17: 73484187 | M17: 284924609 | N17: 299625132 | O17: 345995197 | P17: TRUE | R17: 0919626108 | S17: Needs follow-up | T17: OP-016-A | U17: SKU-53309 | V17: A | W17: =SUM(tblData[@Sales_Q1]:tblData[@Sales_Q4]) -> 0 | X17: =IF(tblData[@Target]=0,0, SUM(tblData[@Sales_Q1]:tblData[@Sales_Q4])/tblData[@Target]) -> 0 | Y17: =IF([@[Achieved_%]]>=1,"Yes","No") -> 0 | Z17: =RIGHT(tblData[@Email],LEN(tblData[@Email])-FIND("@",tblData[@Email])) -> 0 | AA17: =YEAR(tblData[@Join_Date]) -> 0 | AB17: {=_xlfn.XLOOKUP(tblData[@Department],Dept!A:A,Dept!B:B,"N/A")} -> 0 | AC17: {=_xlfn.XLOOKUP(tblData[@Region],Region!A:A,Region!B:B,"N/A")} -> 0 | AD17: =UPPER(tblData[@Name]) -> 0 | AE17: =[@Total_Sales]-tblData[@Target] -> 0 | AF17: =IFERROR(VALUE(MID(tblData[@Code],4,3)),"ERR") -> 0
A18: E0017 | B18: Vũ Khánh | C18: Marketing | D18: HN | E18: khánh.vũ@example.com | F18: 44843 | G18: 22643995 | H18: 4771869 | I18: 154.9 | J18: 0 | K18: 125415325 | L18: 85563453 | M18: 218973642 | N18: 369309439 | O18: 396703609 | P18: FALSE | Q18: E0004 | R18: 0932582524 | S18: OK | T18: MA-017-C | U18: SKU-63354 | V18: C | W18: =SUM(tblData[@Sales_Q1]:tblData[@Sales_Q4]) -> 0 | X18: =IF(tblData[@Target]=0,0, SUM(tblData[@Sales_Q1]:tblData[@Sales_Q4])/tblData[@Target]) -> 0 | Y18: =IF([@[Achieved_%]]>=1,"Yes","No") -> 0 | Z18: =RIGHT(tblData[@Email],LEN(tblData[@Email])-FIND("@",tblData[@Email])) -> 0 | AA18: =YEAR(tblData[@Join_Date]) -> 0 | AB18: {=_xlfn.XLOOKUP(tblData[@Department],Dept!A:A,Dept!B:B,"N/A")} -> 0 | AC18: {=_xlfn.XLOOKUP(tblData[@Region],Region!A:A,Region!B:B,"N/A")} -> 0 | AD18: =UPPER(tblData[@Name]) -> 0 | AE18: =[@Total_Sales]-tblData[@Target] -> 0 | AF18: =IFERROR(VALUE(MID(tblData[@Code],4,3)),"ERR") -> 0
A19: E0018 | B19: Phan Phúc | C19: IT | D19: CT | E19: phúc.phan@example.com | F19: 45202 | G19: 31637222 | H19: 7319767 | I19: 161.8 | J19: 0 | K19: 147453338 | L19: 273801277 | M19: 52235000 | N19: 342121203 | O19: 590529868 | P19: TRUE | Q19: E0001 | R19: 0966692553 | S19: thử nghiệm | T19: IT-018-B | U19: SKU-17944 | V19: B | W19: =SUM(tblData[@Sales_Q1]:tblData[@Sales_Q4]) -> 0 | X19: =IF(tblData[@Target]=0,0, SUM(tblData[@Sales_Q1]:tblData[@Sales_Q4])/tblData[@Target]) -> 0 | Y19: =IF([@[Achieved_%]]>=1,"Yes","No") -> 0 | Z19: =RIGHT(tblData[@Email],LEN(tblData[@Email])-FIND("@",tblData[@Email])) -> 0 | AA19: =YEAR(tblData[@Join_Date]) -> 0 | AB19: {=_xlfn.XLOOKUP(tblData[@Department],Dept!A:A,Dept!B:B,"N/A")} -> 0 | AC19: {=_xlfn.XLOOKUP(tblData[@Region],Region!A:A,Region!B:B,"N/A")} -> 0 | AD19: =UPPER(tblData[@Name]) -> 0 | AE19: =[@Total_Sales]-tblData[@Target] -> 0 | AF19: =IFERROR(VALUE(MID(tblData[@Code],4,3)),"ERR") -> 0
A20: E0019 | B20: Phạm Khánh | C20: Marketing | D20: CT | E20: khánh.phạm@contoso.vn | F20: 45599 | G20: 41957122 | H20: 2156194 | I20: 180.9 | J20: 4.9 | K20: 232153864 | L20: 339635552 | M20: 133375337 | N20: 341669966 | O20: 872804538 | P20: FALSE | Q20: E0004 | R20: 0918434500 | S20: VIP | T20: MA-019-A | U20: SKU-42742 | V20: A | W20: =SUM(tblData[@Sales_Q1]:tblData[@Sales_Q4]) -> 0 | X20: =IF(tblData[@Target]=0,0, SUM(tblData[@Sales_Q1]:tblData[@Sales_Q4])/tblData[@Target]) -> 0 | Y20: =IF([@[Achieved_%]]>=1,"Yes","No") -> 0 | Z20: =RIGHT(tblData[@Email],LEN(tblData[@Email])-FIND("@",tblData[@Email])) -> 0 | AA20: =YEAR(tblData[@Join_Date]) -> 0 | AB20: {=_xlfn.XLOOKUP(tblData[@Department],Dept!A:A,Dept!B:B,"N/A")} -> 0 | AC20: {=_xlfn.XLOOKUP(tblData[@Region],Region!A:A,Region!B:B,"N/A")} -> 0 | AD20: =UPPER(tblData[@Name]) -> 0 | AE20: =[@Total_Sales]-tblData[@Target] -> 0 | AF20: =IFERROR(VALUE(MID(tblData[@Code],4,3)),"ERR") -> 0
A21: E0020 | B21: Nguyễn An | C21: Sales | D21: HN | E21: an.nguyễn@company.vn | F21: 45228 | G21: 8061087 | H21: 1239457 | I21: 196.2 | J21: 20.2 | K21: 328710077 | L21: 66816569 | M21: 57654909 | N21: 356249510 | O21: 368520688 | P21: FALSE | Q21: E0002 | R21: 0903762152 | S21: VIP | T21: SA-020-A | U21: SKU-62565 | V21: A | W21: =SUM(tblData[@Sales_Q1]:tblData[@Sales_Q4]) -> 0 | X21: =IF(tblData[@Target]=0,0, SUM(tblData[@Sales_Q1]:tblData[@Sales_Q4])/tblData[@Target]) -> 0 | Y21: =IF([@[Achieved_%]]>=1,"Yes","No") -> 0 | Z21: =RIGHT(tblData[@Email],LEN(tblData[@Email])-FIND("@",tblData[@Email])) -> 0 | AA21: =YEAR(tblData[@Join_Date]) -> 0 | AB21: {=_xlfn.XLOOKUP(tblData[@Department],Dept!A:A,Dept!B:B,"N/A")} -> 0 | AC21: {=_xlfn.XLOOKUP(tblData[@Region],Region!A:A,Region!B:B,"N/A")} -> 0 | AD21: =UPPER(tblData[@Name]) -> 0 | AE21: =[@Total_Sales]-tblData[@Target] -> 0 | AF21: =IFERROR(VALUE(MID(tblData[@Code],4,3)),"ERR") -> 0
A22: E0021 | B22: Phan Minh | C22: IT | D22: DN | E22: minh.phan@contoso.vn | F22: 45467 | G22: 23421040 | H22: 5844675 | I22: 161.3 | J22: 0 | K22: 61506305 | L22: 204777819 | M22: 271099573 | N22: 191951830 | O22: 273035620 | P22: FALSE | Q22: E0003 | R22: 0902022698 | S22: Needs follow-up | T22: IT-021-B | U22: SKU-38534 | V22: B | W22: =SUM(tblData[@Sales_Q1]:tblData[@Sales_Q4]) -> 0 | X22: =IF(tblData[@Target]=0,0, SUM(tblData[@Sales_Q1]:tblData[@Sales_Q4])/tblData[@Target]) -> 0 | Y22: =IF([@[Achieved_%]]>=1,"Yes","No") -> 0 | Z22: =RIGHT(tblData[@Email],LEN(tblData[@Email])-FIND("@",tblData[@Email])) -> 0 | AA22: =YEAR(tblData[@Join_Date]) -> 0 | AB22: {=_xlfn.XLOOKUP(tblData[@Department],Dept!A:A,Dept!B:B,"N/A")} -> 0 | AC22: {=_xlfn.XLOOKUP(tblData[@Region],Region!A:A,Region!B:B,"N/A")} -> 0 | AD22: =UPPER(tblData[@Name]) -> 0 | AE22: =[@Total_Sales]-tblData[@Target] -> 0 | AF22: =IFERROR(VALUE(MID(tblData[@Code],4,3)),"ERR") -> 0
A23: E0022 | B23: Nguyễn Bình | C23: Marketing | D23: CT | E23: bình.nguyễn@contoso.vn | F23: 45590 | G23: 16658144 | H23: 2946330 | I23: 194.5 | J23: 18.5 | K23: 182863028 | L23: 362601305 | M23: 277174085 | N23: 252445635 | O23: 497262390 | P23: TRUE | Q23: E0005 | R23: 0922149597 | S23: VIP | T23: MA-022-C | U23: SKU-20500 | V23: C | W23: =SUM(tblData[@Sales_Q1]:tblData[@Sales_Q4]) -> 0 | X23: =IF(tblData[@Target]=0,0, SUM(tblData[@Sales_Q1]:tblData[@Sales_Q4])/tblData[@Target]) -> 0 | Y23: =IF([@[Achieved_%]]>=1,"Yes","No") -> 0 | Z23: =RIGHT(tblData[@Email],LEN(tblData[@Email])-FIND("@",tblData[@Email])) -> 0 | AA23: =YEAR(tblData[@Join_Date]) -> 0 | AB23: {=_xlfn.XLOOKUP(tblData[@Department],Dept!A:A,Dept!B:B,"N/A")} -> 0 | AC23: {=_xlfn.XLOOKUP(tblData[@Region],Region!A:A,Region!B:B,"N/A")} -> 0 | AD23: =UPPER(tblData[@Name]) -> 0 | AE23: =[@Total_Sales]-tblData[@Target] -> 0 | AF23: =IFERROR(VALUE(MID(tblData[@Code],4,3)),"ERR") -> 0
A24: E0023 | B24: Phạm Quân | C24: Sales | D24: HP | E24: quân.phạm@company.vn | F24: 44033 | G24: 22012538 | H24: 2166737 | I24: 204.3 | J24: 28.3 | K24: 81378291 | L24: 86634821 | M24: 152325205 | N24: 203651082 | O24: 435322750 | P24: TRUE | Q24: E0004 | R24: 0999770838 | S24: Needs follow-up | T24: SA-023-A | U24: SKU-96163 | V24: A | W24: =SUM(tblData[@Sales_Q1]:tblData[@Sales_Q4]) -> 0 | X24: =IF(tblData[@Target]=0,0, SUM(tblData[@Sales_Q1]:tblData[@Sales_Q4])/tblData[@Target]) -> 0 | Y24: =IF([@[Achieved_%]]>=1,"Yes","No") -> 0 | Z24: =RIGHT(tblData[@Email],LEN(tblData[@Email])-FIND("@",tblData[@Email])) -> 0 | AA24: =YEAR(tblData[@Join_Date]) -> 0 | AB24: {=_xlfn.XLOOKUP(tblData[@Department],Dept!A:A,Dept!B:B,"N/A")} -> 0 | AC24: {=_xlfn.XLOOKUP(tblData[@Region],Region!A:A,Region!B:B,"N/A")} -> 0 | AD24: =UPPER(tblData[@Name]) -> 0 | AE24: =[@Total_Sales]-tblData[@Target] -> 0 | AF24: =IFERROR(VALUE(MID(tblData[@Code],4,3)),"ERR") -> 0
A25: E0024 | B25: Phạm Oanh | C25: HR | D25: DN | E25: oanh.phạm@example.com | F25: 44582 | G25: 14314127 | H25: 3107031 | I25: 165.7 | J25: 0 | K25: 314219973 | L25: 354138703 | M25: 225127900 | N25: 376241019 | O25: 912633146 | P25: TRUE | Q25: E0003 | R25: 0952217071 | S25: đã ký HĐ | T25: HR-024-B | U25: SKU-69929 | V25: B | W25: =SUM(tblData[@Sales_Q1]:tblData[@Sales_Q4]) -> 0 | X25: =IF(tblData[@Target]=0,0, SUM(tblData[@Sales_Q1]:tblData[@Sales_Q4])/tblData[@Target]) -> 0 | Y25: =IF([@[Achieved_%]]>=1,"Yes","No") -> 0 | Z25: =RIGHT(tblData[@Email],LEN(tblData[@Email])-FIND("@",tblData[@Email])) -> 0 | AA25: =YEAR(tblData[@Join_Date]) -> 0 | AB25: {=_xlfn.XLOOKUP(tblData[@Department],Dept!A:A,Dept!B:B,"N/A")} -> 0 | AC25: {=_xlfn.XLOOKUP(tblData[@Region],Region!A:A,Region!B:B,"N/A")} -> 0 | AD25: =UPPER(tblData[@Name]) -> 0 | AE25: =[@Total_Sales]-tblData[@Target] -> 0 | AF25: =IFERROR(VALUE(MID(tblData[@Code],4,3)),"ERR") -> 0
A26: E0025 | B26: Đặng Duy | C26: Sales | D26: HP | E26: duy.đặng@company.vn | F26: 44233 | G26: 42465113 | H26: 6472473 | I26: 158.1 | J26: 0 | K26: 136641503 | L26: 262027187 | M26: 331420264 | N26: 333200416 | O26: 783816999 | P26: TRUE | Q26: E0003 | R26: 0937199635 | S26: thử nghiệm | T26: SA-025-A | U26: SKU-19016 | V26: A | W26: =SUM(tblData[@Sales_Q1]:tblData[@Sales_Q4]) -> 0 | X26: =IF(tblData[@Target]=0,0, SUM(tblData[@Sales_Q1]:tblData[@Sales_Q4])/tblData[@Target]) -> 0 | Y26: =IF([@[Achieved_%]]>=1,"Yes","No") -> 0 | Z26: =RIGHT(tblData[@Email],LEN(tblData[@Email])-FIND("@",tblData[@Email])) -> 0 | AA26: =YEAR(tblData[@Join_Date]) -> 0 | AB26: {=_xlfn.XLOOKUP(tblData[@Department],Dept!A:A,Dept!B:B,"N/A")} -> 0 | AC26: {=_xlfn.XLOOKUP(tblData[@Region],Region!A:A,Region!B:B,"N/A")} -> 0 | AD26: =UPPER(tblData[@Name]) -> 0 | AE26: =[@Total_Sales]-tblData[@Target] -> 0 | AF26: =IFERROR(VALUE(MID(tblData[@Code],4,3)),"ERR") -> 0
A27: E0026 | B27: Vũ Ngọc | C27: Marketing | D27: HP | E27: ngọc.vũ@example.com | F27: 45494 | G27: 17132582 | H27: 4066349 | I27: 151 | J27: 0 | K27: 263432470 | L27: 228017694 | M27: 60047453 | N27: 354016681 | O27: 184109026 | P27: TRUE | R27: 0925437001 | S27: VIP | T27: MA-026-A | U27: SKU-23577 | V27: A | W27: =SUM(tblData[@Sales_Q1]:tblData[@Sales_Q4]) -> 0 | X27: =IF(tblData[@Target]=0,0, SUM(tblData[@Sales_Q1]:tblData[@Sales_Q4])/tblData[@Target]) -> 0 | Y27: =IF([@[Achieved_%]]>=1,"Yes","No") -> 0 | Z27: =RIGHT(tblData[@Email],LEN(tblData[@Email])-FIND("@",tblData[@Email])) -> 0 | AA27: =YEAR(tblData[@Join_Date]) -> 0 | AB27: {=_xlfn.XLOOKUP(tblData[@Department],Dept!A:A,Dept!B:B,"N/A")} -> 0 | AC27: {=_xlfn.XLOOKUP(tblData[@Region],Region!A:A,Region!B:B,"N/A")} -> 0 | AD27: =UPPER(tblData[@Name]) -> 0 | AE27: =[@Total_Sales]-tblData[@Target] -> 0 | AF27: =IFERROR(VALUE(MID(tblData[@Code],4,3)),"ERR") -> 0
A28: E0027 | B28: Võ Giang | C28: Finance | D28: DN | E28: giang.võ@company.vn | F28: 44093 | G28: 24037627 | H28: 2042981 | I28: 218.6 | J28: 42.6 | K28: 121450611 | L28: 177348283 | M28: 96510960 | N28: 145415947 | O28: 400368452 | P28: TRUE | Q28: E0002 | R28: 0949479356 | S28: Needs follow-up | T28: FI-027-C | U28: SKU-93130 | V28: C | W28: =SUM(tblData[@Sales_Q1]:tblData[@Sales_Q4]) -> 0 | X28: =IF(tblData[@Target]=0,0, SUM(tblData[@Sales_Q1]:tblData[@Sales_Q4])/tblData[@Target]) -> 0 | Y28: =IF([@[Achieved_%]]>=1,"Yes","No") -> 0 | Z28: =RIGHT(tblData[@Email],LEN(tblData[@Email])-FIND("@",tblData[@Email])) -> 0 | AA28: =YEAR(tblData[@Join_Date]) -> 0 | AB28: {=_xlfn.XLOOKUP(tblData[@Department],Dept!A:A,Dept!B:B,"N/A")} -> 0 | AC28: {=_xlfn.XLOOKUP(tblData[@Region],Region!A:A,Region!B:B,"N/A")} -> 0 | AD28: =UPPER(tblData[@Name]) -> 0 | AE28: =[@Total_Sales]-tblData[@Target] -> 0 | AF28: =IFERROR(VALUE(MID(tblData[@Code],4,3)),"ERR") -> 0
A29: E0028 | B29: Nguyễn Châu | C29: Ops | D29: CT | E29: châu.nguyễn@contoso.vn | F29: 44891 | G29: 40797855 | H29: 7205729 | I29: 167.1 | J29: 0 | K29: 373659410 | L29: 144962818 | M29: 101910807 | N29: 176736437 | O29: 278314487 | P29: TRUE | Q29: E0002 | R29: 0943710895 | S29: đã ký HĐ | T29: OP-028-B | U29: SKU-93507 | V29: B | W29: =SUM(tblData[@Sales_Q1]:tblData[@Sales_Q4]) -> 0 | X29: =IF(tblData[@Target]=0,0, SUM(tblData[@Sales_Q1]:tblData[@Sales_Q4])/tblData[@Target]) -> 0 | Y29: =IF([@[Achieved_%]]>=1,"Yes","No") -> 0 | Z29: =RIGHT(tblData[@Email],LEN(tblData[@Email])-FIND("@",tblData[@Email])) -> 0 | AA29: =YEAR(tblData[@Join_Date]) -> 0 | AB29: {=_xlfn.XLOOKUP(tblData[@Department],Dept!A:A,Dept!B:B,"N/A")} -> 0 | AC29: {=_xlfn.XLOOKUP(tblData[@Region],Region!A:A,Region!B:B,"N/A")} -> 0 | AD29: =UPPER(tblData[@Name]) -> 0 | AE29: =[@Total_Sales]-tblData[@Target] -> 0 | AF29: =IFERROR(VALUE(MID(tblData[@Code],4,3)),"ERR") -> 0
A30: E0029 | B30: Võ Trang | C30: Marketing | D30: HCM | E30: trang.võ@company.vn | F30: 45527 | G30: 14041495 | H30: 3091736 | I30: 214.9 | J30: 38.9 | K30: 201786915 | L30: 151164453 | M30: 238928103 | N30: 396546429 | O30: 189501026 | P30: TRUE | R30: 0981604451 | S30: pending | T30: MA-029-A | U30: SKU-29536 | V30: A | W30: =SUM(tblData[@Sales_Q1]:tblData[@Sales_Q4]) -> 0 | X30: =IF(tblData[@Target]=0,0, SUM(tblData[@Sales_Q1]:tblData[@Sales_Q4])/tblData[@Target]) -> 0 | Y30: =IF([@[Achieved_%]]>=1,"Yes","No") -> 0 | Z30: =RIGHT(tblData[@Email],LEN(tblData[@Email])-FIND("@",tblData[@Email])) -> 0 | AA30: =YEAR(tblData[@Join_Date]) -> 0 | AB30: {=_xlfn.XLOOKUP(tblData[@Department],Dept!A:A,Dept!B:B,"N/A")} -> 0 | AC30: {=_xlfn.XLOOKUP(tblData[@Region],Region!A:A,Region!B:B,"N/A")} -> 0 | AD30: =UPPER(tblData[@Name]) -> 0 | AE30: =[@Total_Sales]-tblData[@Target] -> 0 | AF30: =IFERROR(VALUE(MID(tblData[@Code],4,3)),"ERR") -> 0
A31: E0030 | B31: Võ Giang | C31: IT | D31: HN | E31: giang.võ@contoso.vn | F31: 44966 | G31: 41163773 | H31: 9798076 | I31: 217.9 | J31: 41.9 | K31: 195689489 | L31: 203794431 | M31: 287785965 | N31: 259310033 | O31: 974183605 | P31: TRUE | Q31: E0001 | R31: 0935186414 | S31: VIP | T31: IT-030-A | U31: SKU-56898 | V31: A | W31: =SUM(tblData[@Sales_Q1]:tblData[@Sales_Q4]) -> 0 | X31: =IF(tblData[@Target]=0,0, SUM(tblData[@Sales_Q1]:tblData[@Sales_Q4])/tblData[@Target]) -> 0 | Y31: =IF([@[Achieved_%]]>=1,"Yes","No") -> 0 | Z31: =RIGHT(tblData[@Email],LEN(tblData[@Email])-FIND("@",tblData[@Email])) -> 0 | AA31: =YEAR(tblData[@Join_Date]) -> 0 | AB31: {=_xlfn.XLOOKUP(tblData[@Department],Dept!A:A,Dept!B:B,"N/A")} -> 0 | AC31: {=_xlfn.XLOOKUP(tblData[@Region],Region!A:A,Region!B:B,"N/A")} -> 0 | AD31: =UPPER(tblData[@Name]) -> 0 | AE31: =[@Total_Sales]-tblData[@Target] -> 0 | AF31: =IFERROR(VALUE(MID(tblData[@Code],4,3)),"ERR") -> 0
A32: E0031 | B32: Huỳnh Trang | C32: Marketing | D32: HN | E32: trang.huỳnh@example.com | F32: 45017 | G32: 31705256 | H32: 2700813 | I32: 141.4 | J32: 0 | K32: 373839252 | L32: 281166767 | M32: 155797503 | N32: 190071312 | O32: 399369215 | P32: TRUE | R32: 0961415846 | S32: OK | T32: MA-031-A | U32: SKU-33206 | V32: A | W32: =SUM(tblData[@Sales_Q1]:tblData[@Sales_Q4]) -> 0 | X32: =IF(tblData[@Target]=0,0, SUM(tblData[@Sales_Q1]:tblData[@Sales_Q4])/tblData[@Target]) -> 0 | Y32: =IF([@[Achieved_%]]>=1,"Yes","No") -> 0 | Z32: =RIGHT(tblData[@Email],LEN(tblData[@Email])-FIND("@",tblData[@Email])) -> 0 | AA32: =YEAR(tblData[@Join_Date]) -> 0 | AB32: {=_xlfn.XLOOKUP(tblData[@Department],Dept!A:A,Dept!B:B,"N/A")} -> 0 | AC32: {=_xlfn.XLOOKUP(tblData[@Region],Region!A:A,Region!B:B,"N/A")} -> 0 | AD32: =UPPER(tblData[@Name]) -> 0 | AE32: =[@Total_Sales]-tblData[@Target] -> 0 | AF32: =IFERROR(VALUE(MID(tblData[@Code],4,3)),"ERR") -> 0
A33: E0032 | B33: Huỳnh Trang | C33: Ops | D33: HN | E33: trang.huỳnh@example.com | F33: 44887 | G33: 45856186 | H33: 5665218 | I33: 161.2 | J33: 0 | K33: 127729132 | L33: 123214389 | M33: 183568263 | N33: 76365210 | O33: 941967770 | P33: TRUE | Q33: E0001 | R33: 0908896868 | S33: thử nghiệm | T33: OP-032-B | U33: SKU-60140 | V33: B | W33: =SUM(tblData[@Sales_Q1]:tblData[@Sales_Q4]) -> 0 | X33: =IF(tblData[@Target]=0,0, SUM(tblData[@Sales_Q1]:tblData[@Sales_Q4])/tblData[@Target]) -> 0 | Y33: =IF([@[Achieved_%]]>=1,"Yes","No") -> 0 | Z33: =RIGHT(tblData[@Email],LEN(tblData[@Email])-FIND("@",tblData[@Email])) -> 0 | AA33: =YEAR(tblData[@Join_Date]) -> 0 | AB33: {=_xlfn.XLOOKUP(tblData[@Department],Dept!A:A,Dept!B:B,"N/A")} -> 0 | AC33: {=_xlfn.XLOOKUP(tblData[@Region],Region!A:A,Region!B:B,"N/A")} -> 0 | AD33: =UPPER(tblData[@Name]) -> 0 | AE33: =[@Total_Sales]-tblData[@Target] -> 0 | AF33: =IFERROR(VALUE(MID(tblData[@Code],4,3)),"ERR") -> 0
A34: E0033 | B34: Vũ Phúc | C34: Finance | D34: HN | E34: phúc.vũ@company.vn | F34: 44056 | G34: 35180308 | H34: 5295600 | I34: 186.2 | J34: 10.2 | K34: 351691332 | L34: 182166290 | M34: 359255683 | N34: 154436258 | O34: 229688895 | P34: TRUE | Q34: E0004 | R34: 0942164686 | S34: Needs follow-up | T34: FI-033-A | U34: SKU-53025 | V34: A | W34: =SUM(tblData[@Sales_Q1]:tblData[@Sales_Q4]) -> 0 | X34: =IF(tblData[@Target]=0,0, SUM(tblData[@Sales_Q1]:tblData[@Sales_Q4])/tblData[@Target]) -> 0 | Y34: =IF([@[Achieved_%]]>=1,"Yes","No") -> 0 | Z34: =RIGHT(tblData[@Email],LEN(tblData[@Email])-FIND("@",tblData[@Email])) -> 0 | AA34: =YEAR(tblData[@Join_Date]) -> 0 | AB34: {=_xlfn.XLOOKUP(tblData[@Department],Dept!A:A,Dept!B:B,"N/A")} -> 0 | AC34: {=_xlfn.XLOOKUP(tblData[@Region],Region!A:A,Region!B:B,"N/A")} -> 0 | AD34: =UPPER(tblData[@Name]) -> 0 | AE34: =[@Total_Sales]-tblData[@Target] -> 0 | AF34: =IFERROR(VALUE(MID(tblData[@Code],4,3)),"ERR") -> 0
A35: E0034 | B35: Võ Quân | C35: Ops | D35: HP | E35: quân.võ@example.com | F35: 44903 | G35: 30487056 | H35: 7588536 | I35: 177.6 | J35: 1.6 | K35: 176960685 | L35: 221216244 | M35: 86481541 | N35: 116385640 | O35: 915872407 | P35: TRUE | Q35: E0003 | R35: 0995453786 | S35: VIP | T35: OP-034-B | U35: SKU-33405 | V35: B | W35: =SUM(tblData[@Sales_Q1]:tblData[@Sales_Q4]) -> 0 | X35: =IF(tblData[@Target]=0,0, SUM(tblData[@Sales_Q1]:tblData[@Sales_Q4])/tblData[@Target]) -> 0 | Y35: =IF([@[Achieved_%]]>=1,"Yes","No") -> 0 | Z35: =RIGHT(tblData[@Email],LEN(tblData[@Email])-FIND("@",tblData[@Email])) -> 0 | AA35: =YEAR(tblData[@Join_Date]) -> 0 | AB35: {=_xlfn.XLOOKUP(tblData[@Department],Dept!A:A,Dept!B:B,"N/A")} -> 0 | AC35: {=_xlfn.XLOOKUP(tblData[@Region],Region!A:A,Region!B:B,"N/A")} -> 0 | AD35: =UPPER(tblData[@Name]) -> 0 | AE35: =[@Total_Sales]-tblData[@Target] -> 0 | AF35: =IFERROR(VALUE(MID(tblData[@Code],4,3)),"ERR") -> 0
A36: E0035 | B36: Đặng Trang | C36: Finance | D36: DN | E36: trang.đặng@contoso.vn | F36: 45203 | G36: 35097584 | H36: 5635022 | I36: 185.8 | J36: 9.8 | K36: 373609715 | L36: 240906558 | M36: 289216892 | N36: 93369428 | O36: 969956639 | P36: TRUE | Q36: E0005 | R36: 0941744682 | S36: đã ký HĐ | T36: FI-035-B | U36: SKU-34914 | V36: B | W36: =SUM(tblData[@Sales_Q1]:tblData[@Sales_Q4]) -> 0 | X36: =IF(tblData[@Target]=0,0, SUM(tblData[@Sales_Q1]:tblData[@Sales_Q4])/tblData[@Target]) -> 0 | Y36: =IF([@[Achieved_%]]>=1,"Yes","No") -> 0 | Z36: =RIGHT(tblData[@Email],LEN(tblData[@Email])-FIND("@",tblData[@Email])) -> 0 | AA36: =YEAR(tblData[@Join_Date]) -> 0 | AB36: {=_xlfn.XLOOKUP(tblData[@Department],Dept!A:A,Dept!B:B,"N/A")} -> 0 | AC36: {=_xlfn.XLOOKUP(tblData[@Region],Region!A:A,Region!B:B,"N/A")} -> 0 | AD36: =UPPER(tblData[@Name]) -> 0 | AE36: =[@Total_Sales]-tblData[@Target] -> 0 | AF36: =IFERROR(VALUE(MID(tblData[@Code],4,3)),"ERR") -> 0
A37: E0036 | B37: Nguyễn Yến | C37: Marketing | D37: HN | E37: yến.nguyễn@contoso.vn | F37: 45015 | G37: 26992383 | H37: 3969391 | I37: 169.8 | J37: 0 | K37: 134574185 | L37: 312657758 | M37: 355070649 | N37: 286295490 | O37: 450910439 | P37: FALSE | Q37: E0003 | R37: 0953090865 | S37: Needs follow-up | T37: MA-036-B | U37: SKU-91678 | V37: B | W37: =SUM(tblData[@Sales_Q1]:tblData[@Sales_Q4]) -> 0 | X37: =IF(tblData[@Target]=0,0, SUM(tblData[@Sales_Q1]:tblData[@Sales_Q4])/tblData[@Target]) -> 0 | Y37: =IF([@[Achieved_%]]>=1,"Yes","No") -> 0 | Z37: =RIGHT(tblData[@Email],LEN(tblData[@Email])-FIND("@",tblData[@Email])) -> 0 | AA37: =YEAR(tblData[@Join_Date]) -> 0 | AB37: {=_xlfn.XLOOKUP(tblData[@Department],Dept!A:A,Dept!B:B,"N/A")} -> 0 | AC37: {=_xlfn.XLOOKUP(tblData[@Region],Region!A:A,Region!B:B,"N/A")} -> 0 | AD37: =UPPER(tblData[@Name]) -> 0 | AE37: =[@Total_Sales]-tblData[@Target] -> 0 | AF37: =IFERROR(VALUE(MID(tblData[@Code],4,3)),"ERR") -> 0
A38: E0037 | B38: Võ Ngọc | C38: Ops | D38: CT | E38: ngọc.võ@contoso.vn | F38: 44516 | G38: 22716695 | H38: 2085023 | I38: 193.7 | J38: 17.7 | K38: 114785345 | L38: 67882750 | M38: 128725274 | N38: 244521577 | O38: 697063169 | P38: FALSE | Q38: E0005 | R38: 0938053918 | S38: đã ký HĐ | T38: OP-037-B | U38: SKU-26683 | V38: B | W38: =SUM(tblData[@Sales_Q1]:tblData[@Sales_Q4]) -> 0 | X38: =IF(tblData[@Target]=0,0, SUM(tblData[@Sales_Q1]:tblData[@Sales_Q4])/tblData[@Target]) -> 0 | Y38: =IF([@[Achieved_%]]>=1,"Yes","No") -> 0 | Z38: =RIGHT(tblData[@Email],LEN(tblData[@Email])-FIND("@",tblData[@Email])) -> 0 | AA38: =YEAR(tblData[@Join_Date]) -> 0 | AB38: {=_xlfn.XLOOKUP(tblData[@Department],Dept!A:A,Dept!B:B,"N/A")} -> 0 | AC38: {=_xlfn.XLOOKUP(tblData[@Region],Region!A:A,Region!B:B,"N/A")} -> 0 | AD38: =UPPER(tblData[@Name]) -> 0 | AE38: =[@Total_Sales]-tblData[@Target] -> 0 | AF38: =IFERROR(VALUE(MID(tblData[@Code],4,3)),"ERR") -> 0
A39: E0038 | B39: Lê Ngọc | C39: IT | D39: HP | E39: ngọc.lê@company.vn | F39: 44615 | G39: 29130343 | H39: 5517378 | I39: 196.2 | J39: 20.2 | K39: 276860070 | L39: 237225564 | M39: 249759529 | N39: 304954230 | O39: 879203225 | P39: TRUE | Q39: E0004 | R39: 0996406444 | S39: đã ký HĐ | T39: IT-038-A | U39: SKU-86019 | V39: A | W39: =SUM(tblData[@Sales_Q1]:tblData[@Sales_Q4]) -> 0 | X39: =IF(tblData[@Target]=0,0, SUM(tblData[@Sales_Q1]:tblData[@Sales_Q4])/tblData[@Target]) -> 0 | Y39: =IF([@[Achieved_%]]>=1,"Yes","No") -> 0 | Z39: =RIGHT(tblData[@Email],LEN(tblData[@Email])-FIND("@",tblData[@Email])) -> 0 | AA39: =YEAR(tblData[@Join_Date]) -> 0 | AB39: {=_xlfn.XLOOKUP(tblData[@Department],Dept!A:A,Dept!B:B,"N/A")} -> 0 | AC39: {=_xlfn.XLOOKUP(tblData[@Region],Region!A:A,Region!B:B,"N/A")} -> 0 | AD39: =UPPER(tblData[@Name]) -> 0 | AE39: =[@Total_Sales]-tblData[@Target] -> 0 | AF39: =IFERROR(VALUE(MID(tblData[@Code],4,3)),"ERR") -> 0
A40: E0039 | B40: Vũ Khánh | C40: Marketing | D40: CT | E40: khánh.vũ@example.com | F40: 44751 | G40: 17185687 | H40: 3998217 | I40: 180.9 | J40: 4.9 | K40: 56512440 | L40: 62431395 | M40: 257426220 | N40: 347529363 | O40: 794090176 | P40: TRUE | Q40: E0003 | R40: 0996623525 | S40: thử nghiệm | T40: MA-039-C | U40: SKU-77561 | V40: C | W40: =SUM(tblData[@Sales_Q1]:tblData[@Sales_Q4]) -> 0 | X40: =IF(tblData[@Target]=0,0, SUM(tblData[@Sales_Q1]:tblData[@Sales_Q4])/tblData[@Target]) -> 0 | Y40: =IF([@[Achieved_%]]>=1,"Yes","No") -> 0 | Z40: =RIGHT(tblData[@Email],LEN(tblData[@Email])-FIND("@",tblData[@Email])) -> 0 | AA40: =YEAR(tblData[@Join_Date]) -> 0 | AB40: {=_xlfn.XLOOKUP(tblData[@Department],Dept!A:A,Dept!B:B,"N/A")} -> 0 | AC40: {=_xlfn.XLOOKUP(tblData[@Region],Region!A:A,Region!B:B,"N/A")} -> 0 | AD40: =UPPER(tblData[@Name]) -> 0 | AE40: =[@Total_Sales]-tblData[@Target] -> 0 | AF40: =IFERROR(VALUE(MID(tblData[@Code],4,3)),"ERR") -> 0
...

Sheet Dept
A1: Department | B1: Cost_Center | C1: Headcount_Plan
A2: Sales | B2: CC-100 | C2: 10
A3: HR | B3: CC-200 | C3: 6
A4: Finance | B4: CC-300 | C4: 8
A5: IT | B5: CC-400 | C5: 12
A6: Marketing | B6: CC-500 | C6: 7
A7: Ops | B7: CC-600 | C7: 15

Sheet Region
A1: Region | B1: City | C1: Ship_Fee
A2: HCM | B2: Hồ Chí Minh | C2: 25000
A3: HN | B3: Hà Nội | C3: 30000
A4: DN | B4: Đà Nẵng | C4: 35000
A5: CT | B5: Cần Thơ | C5: 40000
A6: HP | B6: Hải Phòng | C6: 45000

Sheet Readme
A1: Mục | B1: Nội dung
A2: Mục đích | B2: Bảng này giúp bạn test nhanh các hàm Excel phổ biến (SUM, AVERAGE, IF, XLOOKUP, TEXT, DATE, v.v.).
A3: Sheet | B3: TestData: dữ liệu chính (đã tạo Table tên tblData).
A4: Sheet | B4: Dept: tra cứu Department → Cost_Center.
A5: Sheet | B5: Region: tra cứu Region → City/Ship_Fee.
A6: Gợi ý công thức | B6: Ví dụ: =SUM(tblData[Sales_Q1]:tblData[Sales_Q4])
A7: Gợi ý công thức | B7: Ví dụ: =XLOOKUP("IT",Dept[Department],Dept[Cost_Center])
A8: Gợi ý công thức | B8: Ví dụ: =TEXT(tblData[@Join_Date],"yyyy-mm")
A9: Gợi ý công thức | B9: Ví dụ: =IF(tblData[@Achieved_%]>=1,"Đạt","Chưa đạt")
A10: Gợi ý công thức | B10: Ví dụ: =RIGHT(tblData[@Email],LEN(tblData[@Email])-FIND("@",tblData[@Email]))
A11: Gợi ý công thức | B11: Ví dụ: =SUMIFS(tblData[Total_Sales],tblData[Region],"HCM",tblData[Department],"Sales")
A12: Gợi ý công thức | B12: Ví dụ: =FILTER(tblData[Email],tblData[Active]=TRUE) (Excel 365)
A13: Mẹo | B13: Bạn có thể tạo PivotTable từ TestData để thực hành tổng hợp dữ liệu.
